Traceback (most recent call last):
  File "c:\users\dudas\anaconda3\envs\wintest\lib\site-packages\jupyter_cache\executors\utils.py", line 56, in single_nb_execution
    record_timing=False,
  File "c:\users\dudas\anaconda3\envs\wintest\lib\site-packages\nbclient\client.py", line 1112, in execute
    return NotebookClient(nb=nb, resources=resources, km=km, **kwargs).execute()
  File "c:\users\dudas\anaconda3\envs\wintest\lib\site-packages\nbclient\util.py", line 74, in wrapped
    return just_run(coro(*args, **kwargs))
  File "c:\users\dudas\anaconda3\envs\wintest\lib\site-packages\nbclient\util.py", line 53, in just_run
    return loop.run_until_complete(coro)
  File "c:\users\dudas\anaconda3\envs\wintest\lib\asyncio\base_events.py", line 587, in run_until_complete
    return future.result()
  File "c:\users\dudas\anaconda3\envs\wintest\lib\site-packages\nbclient\client.py", line 554, in async_execute
    cell, index, execution_count=self.code_cells_executed + 1
  File "c:\users\dudas\anaconda3\envs\wintest\lib\site-packages\nbclient\client.py", line 857, in async_execute_cell
    self._check_raise_for_error(cell, exec_reply)
  File "c:\users\dudas\anaconda3\envs\wintest\lib\site-packages\nbclient\client.py", line 760, in _check_raise_for_error
    raise CellExecutionError.from_cell_and_msg(cell, exec_reply_content)
nbclient.exceptions.CellExecutionError: An error occurred while executing the following cell:
------------------
# Function to add four
def addFour( inValAddFour ):
    middleVal = addTwo( inValAddFour )
    finalAns = addTwo( middleVal )
    print( "#-# Print from In Function" )
    print( "startingVal = ", startingVal )
    print( "middleVal = ", middleVal )
    print( "finalAns = ", finalAns )
    return finalAns
    
#-#-#-#-#-#-#
# Not in the function - this is what runs
startingVal = 10

# Call the function using startingVal as the input parameter
fourAdded = addFour( startingVal )

# Print out some things
print( "\n#-# Print after the function" )
print( "startingVal = ", startingVal )
print( "fourAdded = " , fourAdded )

# This won't work because middleVal was only defined within the function
print( "middleVal = ", middleVal )
------------------

[1;31m---------------------------------------------------------------------------[0m
[1;31mNameError[0m                                 Traceback (most recent call last)
[1;32m<ipython-input-9-b6beff6955a7>[0m in [0;36m<module>[1;34m[0m
[0;32m     22[0m [1;33m[0m[0m
[0;32m     23[0m [1;31m# This won't work because middleVal was only defined within the function[0m[1;33m[0m[1;33m[0m[1;33m[0m[0m
[1;32m---> 24[1;33m [0mprint[0m[1;33m([0m [1;34m"middleVal = "[0m[1;33m,[0m [0mmiddleVal[0m [1;33m)[0m[1;33m[0m[1;33m[0m[0m
[0m
[1;31mNameError[0m: name 'middleVal' is not defined
NameError: name 'middleVal' is not defined

