Traceback (most recent call last):
  File "c:\users\dudas\anaconda3\envs\wintest\lib\site-packages\jupyter_cache\executors\utils.py", line 56, in single_nb_execution
    record_timing=False,
  File "c:\users\dudas\anaconda3\envs\wintest\lib\site-packages\nbclient\client.py", line 1112, in execute
    return NotebookClient(nb=nb, resources=resources, km=km, **kwargs).execute()
  File "c:\users\dudas\anaconda3\envs\wintest\lib\site-packages\nbclient\util.py", line 74, in wrapped
    return just_run(coro(*args, **kwargs))
  File "c:\users\dudas\anaconda3\envs\wintest\lib\site-packages\nbclient\util.py", line 53, in just_run
    return loop.run_until_complete(coro)
  File "c:\users\dudas\anaconda3\envs\wintest\lib\asyncio\base_events.py", line 587, in run_until_complete
    return future.result()
  File "c:\users\dudas\anaconda3\envs\wintest\lib\site-packages\nbclient\client.py", line 554, in async_execute
    cell, index, execution_count=self.code_cells_executed + 1
  File "c:\users\dudas\anaconda3\envs\wintest\lib\site-packages\nbclient\client.py", line 857, in async_execute_cell
    self._check_raise_for_error(cell, exec_reply)
  File "c:\users\dudas\anaconda3\envs\wintest\lib\site-packages\nbclient\client.py", line 760, in _check_raise_for_error
    raise CellExecutionError.from_cell_and_msg(cell, exec_reply_content)
nbclient.exceptions.CellExecutionError: An error occurred while executing the following cell:
------------------
from IPython.display import HTML, display

alpha = np.array([0.01, 0.01, 0.01, 0.01, 0.01])
data_from_dirichlet = np.around(dirichlet.rvs(alpha, size=5), decimals=1).tolist()
data_for_output = []

temp = []
temp.append("")

for i in range(5):
    temp.append("<em>topic %s</em>" % (i))

data_for_output.append(temp)    
for i in range(len(data_from_dirichlet)):
    temp = []
    temp.append("<em>document %s</em>" % (i))
    for j in n_data[i]:
        temp.append(j)
    data_for_output.append(temp)

display(HTML(
   '<table><tr>{}</tr></table>'.format(
       '</tr><tr>'.join(
           '<td>{}</td>'.format('</td><td>'.join(str(_) for _ in row)) for row in data_for_output)
       )
))
------------------

[1;31m---------------------------------------------------------------------------[0m
[1;31mNameError[0m                                 Traceback (most recent call last)
[1;32m<ipython-input-24-ddb23e70d594>[0m in [0;36m<module>[1;34m[0m
[0;32m     15[0m     [0mtemp[0m [1;33m=[0m [1;33m[[0m[1;33m][0m[1;33m[0m[1;33m[0m[0m
[0;32m     16[0m     [0mtemp[0m[1;33m.[0m[0mappend[0m[1;33m([0m[1;34m"<em>document %s</em>"[0m [1;33m%[0m [1;33m([0m[0mi[0m[1;33m)[0m[1;33m)[0m[1;33m[0m[1;33m[0m[0m
[1;32m---> 17[1;33m     [1;32mfor[0m [0mj[0m [1;32min[0m [0mn_data[0m[1;33m[[0m[0mi[0m[1;33m][0m[1;33m:[0m[1;33m[0m[1;33m[0m[0m
[0m[0;32m     18[0m         [0mtemp[0m[1;33m.[0m[0mappend[0m[1;33m([0m[0mj[0m[1;33m)[0m[1;33m[0m[1;33m[0m[0m
[0;32m     19[0m     [0mdata_for_output[0m[1;33m.[0m[0mappend[0m[1;33m([0m[0mtemp[0m[1;33m)[0m[1;33m[0m[1;33m[0m[0m

[1;31mNameError[0m: name 'n_data' is not defined
NameError: name 'n_data' is not defined

