Traceback (most recent call last):
  File "c:\users\dudas\anaconda3\envs\wintest\lib\site-packages\jupyter_cache\executors\utils.py", line 56, in single_nb_execution
    record_timing=False,
  File "c:\users\dudas\anaconda3\envs\wintest\lib\site-packages\nbclient\client.py", line 1112, in execute
    return NotebookClient(nb=nb, resources=resources, km=km, **kwargs).execute()
  File "c:\users\dudas\anaconda3\envs\wintest\lib\site-packages\nbclient\util.py", line 74, in wrapped
    return just_run(coro(*args, **kwargs))
  File "c:\users\dudas\anaconda3\envs\wintest\lib\site-packages\nbclient\util.py", line 53, in just_run
    return loop.run_until_complete(coro)
  File "c:\users\dudas\anaconda3\envs\wintest\lib\asyncio\base_events.py", line 587, in run_until_complete
    return future.result()
  File "c:\users\dudas\anaconda3\envs\wintest\lib\site-packages\nbclient\client.py", line 554, in async_execute
    cell, index, execution_count=self.code_cells_executed + 1
  File "c:\users\dudas\anaconda3\envs\wintest\lib\site-packages\nbclient\client.py", line 857, in async_execute_cell
    self._check_raise_for_error(cell, exec_reply)
  File "c:\users\dudas\anaconda3\envs\wintest\lib\site-packages\nbclient\client.py", line 760, in _check_raise_for_error
    raise CellExecutionError.from_cell_and_msg(cell, exec_reply_content)
nbclient.exceptions.CellExecutionError: An error occurred while executing the following cell:
------------------
import pandas as pd
import re
import numpy as np
import random 

from sklearn.feature_extraction.text import CountVectorizer
textArray = text.lower().split(" ")
print(len(textArray))
documents = []

print (random.choices(["sadf","asdf","Aewrwe"], k = 2))
for i in range(27):
    documents.append(" ".join(textArray[i*1000:(i+1)*1000]))

print(documents[10][0:100])
cv = CountVectorizer()
# tokenize and build vocab
df = cv.fit_transform(documents)



------------------

[1;31m---------------------------------------------------------------------------[0m
[1;31mModuleNotFoundError[0m                       Traceback (most recent call last)
[1;32m<ipython-input-2-cea6c4b74d00>[0m in [0;36m<module>[1;34m[0m
[0;32m      4[0m [1;32mimport[0m [0mrandom[0m[1;33m[0m[1;33m[0m[0m
[0;32m      5[0m [1;33m[0m[0m
[1;32m----> 6[1;33m [1;32mfrom[0m [0msklearn[0m[1;33m.[0m[0mfeature_extraction[0m[1;33m.[0m[0mtext[0m [1;32mimport[0m [0mCountVectorizer[0m[1;33m[0m[1;33m[0m[0m
[0m[0;32m      7[0m [0mtextArray[0m [1;33m=[0m [0mtext[0m[1;33m.[0m[0mlower[0m[1;33m([0m[1;33m)[0m[1;33m.[0m[0msplit[0m[1;33m([0m[1;34m" "[0m[1;33m)[0m[1;33m[0m[1;33m[0m[0m
[0;32m      8[0m [0mprint[0m[1;33m([0m[0mlen[0m[1;33m([0m[0mtextArray[0m[1;33m)[0m[1;33m)[0m[1;33m[0m[1;33m[0m[0m

[1;31mModuleNotFoundError[0m: No module named 'sklearn'
ModuleNotFoundError: No module named 'sklearn'

